INFO 2024-01-17 02:30:19,288 autoreload 19520 9484 Watching for file changes with StatReloader
INFO 2024-01-17 02:30:23,074 basehttp 19520 9556 "GET / HTTP/1.1" 200 0
WARNING 2024-01-17 02:30:23,171 log 19520 9556 Not Found: /favicon.ico
WARNING 2024-01-17 02:30:23,172 basehttp 19520 9556 "GET /favicon.ico HTTP/1.1" 404 2535
INFO 2024-01-17 02:30:25,973 basehttp 19520 9556 "GET / HTTP/1.1" 200 0
INFO 2024-01-17 02:30:49,580 autoreload 16900 3776 Watching for file changes with StatReloader
INFO 2024-01-17 02:30:51,715 basehttp 16900 14244 "GET / HTTP/1.1" 200 34
<<<<<<< HEAD
INFO 2024-01-17 03:15:11,339 autoreload 3132 10900 Watching for file changes with StatReloader
WARNING 2024-01-17 03:15:28,526 log 3132 13684 Not Found: /
WARNING 2024-01-17 03:15:28,527 basehttp 3132 13684 "GET / HTTP/1.1" 404 2493
INFO 2024-01-17 03:15:34,650 basehttp 3132 13684 "GET /tele_api HTTP/1.1" 301 0
ERROR 2024-01-17 03:15:34,698 log 3132 6904 Internal Server Error: /tele_api/
Traceback (most recent call last):
  File "F:\my_linux_project\terminal_bot_serv\web_admin_telebot\venv\Lib\site-packages\django\contrib\sessions\backends\base.py", line 187, in _get_session
    return self._session_cache
           ^^^^^^^^^^^^^^^^^^^
AttributeError: 'SessionStore' object has no attribute '_session_cache'

During handling of the above exception, another exception occurred:

Traceback (most recent call last):
  File "F:\my_linux_project\terminal_bot_serv\web_admin_telebot\venv\Lib\site-packages\django\db\backends\utils.py", line 105, in _execute
    return self.cursor.execute(sql, params)
           ^^^^^^^^^^^^^^^^^^^^^^^^^^^^^^^^
  File "F:\my_linux_project\terminal_bot_serv\web_admin_telebot\venv\Lib\site-packages\django\db\backends\sqlite3\base.py", line 328, in execute
    return super().execute(query, params)
           ^^^^^^^^^^^^^^^^^^^^^^^^^^^^^^
sqlite3.OperationalError: no such table: django_session

The above exception was the direct cause of the following exception:

Traceback (most recent call last):
  File "F:\my_linux_project\terminal_bot_serv\web_admin_telebot\venv\Lib\site-packages\django\core\handlers\exception.py", line 55, in inner
    response = get_response(request)
               ^^^^^^^^^^^^^^^^^^^^^
  File "F:\my_linux_project\terminal_bot_serv\web_admin_telebot\venv\Lib\site-packages\django\core\handlers\base.py", line 197, in _get_response
    response = wrapped_callback(request, *callback_args, **callback_kwargs)
               ^^^^^^^^^^^^^^^^^^^^^^^^^^^^^^^^^^^^^^^^^^^^^^^^^^^^^^^^^^^^
  File "F:\my_linux_project\terminal_bot_serv\web_admin_telebot\venv\Lib\site-packages\django\views\decorators\csrf.py", line 65, in _view_wrapper
    return view_func(request, *args, **kwargs)
           ^^^^^^^^^^^^^^^^^^^^^^^^^^^^^^^^^^^
  File "F:\my_linux_project\terminal_bot_serv\web_admin_telebot\venv\Lib\site-packages\django\views\generic\base.py", line 104, in view
    return self.dispatch(request, *args, **kwargs)
           ^^^^^^^^^^^^^^^^^^^^^^^^^^^^^^^^^^^^^^^
  File "F:\my_linux_project\terminal_bot_serv\web_admin_telebot\venv\Lib\site-packages\rest_framework\views.py", line 509, in dispatch
    response = self.handle_exception(exc)
               ^^^^^^^^^^^^^^^^^^^^^^^^^^
  File "F:\my_linux_project\terminal_bot_serv\web_admin_telebot\venv\Lib\site-packages\rest_framework\views.py", line 469, in handle_exception
    self.raise_uncaught_exception(exc)
  File "F:\my_linux_project\terminal_bot_serv\web_admin_telebot\venv\Lib\site-packages\rest_framework\views.py", line 480, in raise_uncaught_exception
    raise exc
  File "F:\my_linux_project\terminal_bot_serv\web_admin_telebot\venv\Lib\site-packages\rest_framework\views.py", line 497, in dispatch
    self.initial(request, *args, **kwargs)
  File "F:\my_linux_project\terminal_bot_serv\web_admin_telebot\venv\Lib\site-packages\rest_framework\views.py", line 414, in initial
    self.perform_authentication(request)
  File "F:\my_linux_project\terminal_bot_serv\web_admin_telebot\venv\Lib\site-packages\rest_framework\views.py", line 324, in perform_authentication
    request.user
  File "F:\my_linux_project\terminal_bot_serv\web_admin_telebot\venv\Lib\site-packages\rest_framework\request.py", line 227, in user
    self._authenticate()
  File "F:\my_linux_project\terminal_bot_serv\web_admin_telebot\venv\Lib\site-packages\rest_framework\request.py", line 380, in _authenticate
    user_auth_tuple = authenticator.authenticate(self)
                      ^^^^^^^^^^^^^^^^^^^^^^^^^^^^^^^^
  File "F:\my_linux_project\terminal_bot_serv\web_admin_telebot\venv\Lib\site-packages\rest_framework\authentication.py", line 127, in authenticate
    if not user or not user.is_active:
  File "F:\my_linux_project\terminal_bot_serv\web_admin_telebot\venv\Lib\site-packages\django\utils\functional.py", line 251, in inner
    self._setup()
  File "F:\my_linux_project\terminal_bot_serv\web_admin_telebot\venv\Lib\site-packages\django\utils\functional.py", line 404, in _setup
    self._wrapped = self._setupfunc()
                    ^^^^^^^^^^^^^^^^^
  File "F:\my_linux_project\terminal_bot_serv\web_admin_telebot\venv\Lib\site-packages\django\contrib\auth\middleware.py", line 33, in <lambda>
    request.user = SimpleLazyObject(lambda: get_user(request))
                                            ^^^^^^^^^^^^^^^^^
  File "F:\my_linux_project\terminal_bot_serv\web_admin_telebot\venv\Lib\site-packages\django\contrib\auth\middleware.py", line 13, in get_user
    request._cached_user = auth.get_user(request)
                           ^^^^^^^^^^^^^^^^^^^^^^
  File "F:\my_linux_project\terminal_bot_serv\web_admin_telebot\venv\Lib\site-packages\django\contrib\auth\__init__.py", line 209, in get_user
    user_id = _get_user_session_key(request)
              ^^^^^^^^^^^^^^^^^^^^^^^^^^^^^^
  File "F:\my_linux_project\terminal_bot_serv\web_admin_telebot\venv\Lib\site-packages\django\contrib\auth\__init__.py", line 62, in _get_user_session_key
    return get_user_model()._meta.pk.to_python(request.session[SESSION_KEY])
                                               ~~~~~~~~~~~~~~~^^^^^^^^^^^^^
  File "F:\my_linux_project\terminal_bot_serv\web_admin_telebot\venv\Lib\site-packages\django\contrib\sessions\backends\base.py", line 53, in __getitem__
    return self._session[key]
           ^^^^^^^^^^^^^
  File "F:\my_linux_project\terminal_bot_serv\web_admin_telebot\venv\Lib\site-packages\django\contrib\sessions\backends\base.py", line 192, in _get_session
    self._session_cache = self.load()
                          ^^^^^^^^^^^
  File "F:\my_linux_project\terminal_bot_serv\web_admin_telebot\venv\Lib\site-packages\django\contrib\sessions\backends\db.py", line 42, in load
    s = self._get_session_from_db()
        ^^^^^^^^^^^^^^^^^^^^^^^^^^^
  File "F:\my_linux_project\terminal_bot_serv\web_admin_telebot\venv\Lib\site-packages\django\contrib\sessions\backends\db.py", line 32, in _get_session_from_db
    return self.model.objects.get(
           ^^^^^^^^^^^^^^^^^^^^^^^
  File "F:\my_linux_project\terminal_bot_serv\web_admin_telebot\venv\Lib\site-packages\django\db\models\manager.py", line 87, in manager_method
    return getattr(self.get_queryset(), name)(*args, **kwargs)
           ^^^^^^^^^^^^^^^^^^^^^^^^^^^^^^^^^^^^^^^^^^^^^^^^^^^
  File "F:\my_linux_project\terminal_bot_serv\web_admin_telebot\venv\Lib\site-packages\django\db\models\query.py", line 643, in get
    num = len(clone)
          ^^^^^^^^^^
  File "F:\my_linux_project\terminal_bot_serv\web_admin_telebot\venv\Lib\site-packages\django\db\models\query.py", line 380, in __len__
    self._fetch_all()
  File "F:\my_linux_project\terminal_bot_serv\web_admin_telebot\venv\Lib\site-packages\django\db\models\query.py", line 1926, in _fetch_all
    self._result_cache = list(self._iterable_class(self))
                         ^^^^^^^^^^^^^^^^^^^^^^^^^^^^^^^^
  File "F:\my_linux_project\terminal_bot_serv\web_admin_telebot\venv\Lib\site-packages\django\db\models\query.py", line 91, in __iter__
    results = compiler.execute_sql(
              ^^^^^^^^^^^^^^^^^^^^^
  File "F:\my_linux_project\terminal_bot_serv\web_admin_telebot\venv\Lib\site-packages\django\db\models\sql\compiler.py", line 1562, in execute_sql
    cursor.execute(sql, params)
  File "F:\my_linux_project\terminal_bot_serv\web_admin_telebot\venv\Lib\site-packages\django\db\backends\utils.py", line 122, in execute
    return super().execute(sql, params)
           ^^^^^^^^^^^^^^^^^^^^^^^^^^^^
  File "F:\my_linux_project\terminal_bot_serv\web_admin_telebot\venv\Lib\site-packages\django\db\backends\utils.py", line 79, in execute
    return self._execute_with_wrappers(
           ^^^^^^^^^^^^^^^^^^^^^^^^^^^^
  File "F:\my_linux_project\terminal_bot_serv\web_admin_telebot\venv\Lib\site-packages\django\db\backends\utils.py", line 92, in _execute_with_wrappers
    return executor(sql, params, many, context)
           ^^^^^^^^^^^^^^^^^^^^^^^^^^^^^^^^^^^^
  File "F:\my_linux_project\terminal_bot_serv\web_admin_telebot\venv\Lib\site-packages\django\db\backends\utils.py", line 100, in _execute
    with self.db.wrap_database_errors:
  File "F:\my_linux_project\terminal_bot_serv\web_admin_telebot\venv\Lib\site-packages\django\db\utils.py", line 91, in __exit__
    raise dj_exc_value.with_traceback(traceback) from exc_value
  File "F:\my_linux_project\terminal_bot_serv\web_admin_telebot\venv\Lib\site-packages\django\db\backends\utils.py", line 105, in _execute
    return self.cursor.execute(sql, params)
           ^^^^^^^^^^^^^^^^^^^^^^^^^^^^^^^^
  File "F:\my_linux_project\terminal_bot_serv\web_admin_telebot\venv\Lib\site-packages\django\db\backends\sqlite3\base.py", line 328, in execute
    return super().execute(query, params)
           ^^^^^^^^^^^^^^^^^^^^^^^^^^^^^^
django.db.utils.OperationalError: no such table: django_session
ERROR 2024-01-17 03:15:34,703 basehttp 3132 6904 "GET /tele_api/ HTTP/1.1" 500 234321
INFO 2024-01-17 03:16:38,798 autoreload 18092 9476 Watching for file changes with StatReloader
ERROR 2024-01-17 03:16:44,011 log 18092 20360 Internal Server Error: /tele_api/
Traceback (most recent call last):
  File "F:\my_linux_project\terminal_bot_serv\web_admin_telebot\venv\Lib\site-packages\django\contrib\sessions\backends\base.py", line 187, in _get_session
    return self._session_cache
           ^^^^^^^^^^^^^^^^^^^
AttributeError: 'SessionStore' object has no attribute '_session_cache'

During handling of the above exception, another exception occurred:

Traceback (most recent call last):
  File "F:\my_linux_project\terminal_bot_serv\web_admin_telebot\venv\Lib\site-packages\django\db\backends\utils.py", line 105, in _execute
    return self.cursor.execute(sql, params)
           ^^^^^^^^^^^^^^^^^^^^^^^^^^^^^^^^
  File "F:\my_linux_project\terminal_bot_serv\web_admin_telebot\venv\Lib\site-packages\django\db\backends\sqlite3\base.py", line 328, in execute
    return super().execute(query, params)
           ^^^^^^^^^^^^^^^^^^^^^^^^^^^^^^
sqlite3.OperationalError: no such table: django_session

The above exception was the direct cause of the following exception:

Traceback (most recent call last):
  File "F:\my_linux_project\terminal_bot_serv\web_admin_telebot\venv\Lib\site-packages\django\core\handlers\exception.py", line 55, in inner
    response = get_response(request)
               ^^^^^^^^^^^^^^^^^^^^^
  File "F:\my_linux_project\terminal_bot_serv\web_admin_telebot\venv\Lib\site-packages\django\core\handlers\base.py", line 197, in _get_response
    response = wrapped_callback(request, *callback_args, **callback_kwargs)
               ^^^^^^^^^^^^^^^^^^^^^^^^^^^^^^^^^^^^^^^^^^^^^^^^^^^^^^^^^^^^
  File "F:\my_linux_project\terminal_bot_serv\web_admin_telebot\venv\Lib\site-packages\django\views\decorators\csrf.py", line 65, in _view_wrapper
    return view_func(request, *args, **kwargs)
           ^^^^^^^^^^^^^^^^^^^^^^^^^^^^^^^^^^^
  File "F:\my_linux_project\terminal_bot_serv\web_admin_telebot\venv\Lib\site-packages\django\views\generic\base.py", line 104, in view
    return self.dispatch(request, *args, **kwargs)
           ^^^^^^^^^^^^^^^^^^^^^^^^^^^^^^^^^^^^^^^
  File "F:\my_linux_project\terminal_bot_serv\web_admin_telebot\venv\Lib\site-packages\rest_framework\views.py", line 509, in dispatch
    response = self.handle_exception(exc)
               ^^^^^^^^^^^^^^^^^^^^^^^^^^
  File "F:\my_linux_project\terminal_bot_serv\web_admin_telebot\venv\Lib\site-packages\rest_framework\views.py", line 469, in handle_exception
    self.raise_uncaught_exception(exc)
  File "F:\my_linux_project\terminal_bot_serv\web_admin_telebot\venv\Lib\site-packages\rest_framework\views.py", line 480, in raise_uncaught_exception
    raise exc
  File "F:\my_linux_project\terminal_bot_serv\web_admin_telebot\venv\Lib\site-packages\rest_framework\views.py", line 497, in dispatch
    self.initial(request, *args, **kwargs)
  File "F:\my_linux_project\terminal_bot_serv\web_admin_telebot\venv\Lib\site-packages\rest_framework\views.py", line 414, in initial
    self.perform_authentication(request)
  File "F:\my_linux_project\terminal_bot_serv\web_admin_telebot\venv\Lib\site-packages\rest_framework\views.py", line 324, in perform_authentication
    request.user
  File "F:\my_linux_project\terminal_bot_serv\web_admin_telebot\venv\Lib\site-packages\rest_framework\request.py", line 227, in user
    self._authenticate()
  File "F:\my_linux_project\terminal_bot_serv\web_admin_telebot\venv\Lib\site-packages\rest_framework\request.py", line 380, in _authenticate
    user_auth_tuple = authenticator.authenticate(self)
                      ^^^^^^^^^^^^^^^^^^^^^^^^^^^^^^^^
  File "F:\my_linux_project\terminal_bot_serv\web_admin_telebot\venv\Lib\site-packages\rest_framework\authentication.py", line 127, in authenticate
    if not user or not user.is_active:
  File "F:\my_linux_project\terminal_bot_serv\web_admin_telebot\venv\Lib\site-packages\django\utils\functional.py", line 251, in inner
    self._setup()
  File "F:\my_linux_project\terminal_bot_serv\web_admin_telebot\venv\Lib\site-packages\django\utils\functional.py", line 404, in _setup
    self._wrapped = self._setupfunc()
                    ^^^^^^^^^^^^^^^^^
  File "F:\my_linux_project\terminal_bot_serv\web_admin_telebot\venv\Lib\site-packages\django\contrib\auth\middleware.py", line 33, in <lambda>
    request.user = SimpleLazyObject(lambda: get_user(request))
                                            ^^^^^^^^^^^^^^^^^
  File "F:\my_linux_project\terminal_bot_serv\web_admin_telebot\venv\Lib\site-packages\django\contrib\auth\middleware.py", line 13, in get_user
    request._cached_user = auth.get_user(request)
                           ^^^^^^^^^^^^^^^^^^^^^^
  File "F:\my_linux_project\terminal_bot_serv\web_admin_telebot\venv\Lib\site-packages\django\contrib\auth\__init__.py", line 209, in get_user
    user_id = _get_user_session_key(request)
              ^^^^^^^^^^^^^^^^^^^^^^^^^^^^^^
  File "F:\my_linux_project\terminal_bot_serv\web_admin_telebot\venv\Lib\site-packages\django\contrib\auth\__init__.py", line 62, in _get_user_session_key
    return get_user_model()._meta.pk.to_python(request.session[SESSION_KEY])
                                               ~~~~~~~~~~~~~~~^^^^^^^^^^^^^
  File "F:\my_linux_project\terminal_bot_serv\web_admin_telebot\venv\Lib\site-packages\django\contrib\sessions\backends\base.py", line 53, in __getitem__
    return self._session[key]
           ^^^^^^^^^^^^^
  File "F:\my_linux_project\terminal_bot_serv\web_admin_telebot\venv\Lib\site-packages\django\contrib\sessions\backends\base.py", line 192, in _get_session
    self._session_cache = self.load()
                          ^^^^^^^^^^^
  File "F:\my_linux_project\terminal_bot_serv\web_admin_telebot\venv\Lib\site-packages\django\contrib\sessions\backends\db.py", line 42, in load
    s = self._get_session_from_db()
        ^^^^^^^^^^^^^^^^^^^^^^^^^^^
  File "F:\my_linux_project\terminal_bot_serv\web_admin_telebot\venv\Lib\site-packages\django\contrib\sessions\backends\db.py", line 32, in _get_session_from_db
    return self.model.objects.get(
           ^^^^^^^^^^^^^^^^^^^^^^^
  File "F:\my_linux_project\terminal_bot_serv\web_admin_telebot\venv\Lib\site-packages\django\db\models\manager.py", line 87, in manager_method
    return getattr(self.get_queryset(), name)(*args, **kwargs)
           ^^^^^^^^^^^^^^^^^^^^^^^^^^^^^^^^^^^^^^^^^^^^^^^^^^^
  File "F:\my_linux_project\terminal_bot_serv\web_admin_telebot\venv\Lib\site-packages\django\db\models\query.py", line 643, in get
    num = len(clone)
          ^^^^^^^^^^
  File "F:\my_linux_project\terminal_bot_serv\web_admin_telebot\venv\Lib\site-packages\django\db\models\query.py", line 380, in __len__
    self._fetch_all()
  File "F:\my_linux_project\terminal_bot_serv\web_admin_telebot\venv\Lib\site-packages\django\db\models\query.py", line 1926, in _fetch_all
    self._result_cache = list(self._iterable_class(self))
                         ^^^^^^^^^^^^^^^^^^^^^^^^^^^^^^^^
  File "F:\my_linux_project\terminal_bot_serv\web_admin_telebot\venv\Lib\site-packages\django\db\models\query.py", line 91, in __iter__
    results = compiler.execute_sql(
              ^^^^^^^^^^^^^^^^^^^^^
  File "F:\my_linux_project\terminal_bot_serv\web_admin_telebot\venv\Lib\site-packages\django\db\models\sql\compiler.py", line 1562, in execute_sql
    cursor.execute(sql, params)
  File "F:\my_linux_project\terminal_bot_serv\web_admin_telebot\venv\Lib\site-packages\django\db\backends\utils.py", line 122, in execute
    return super().execute(sql, params)
           ^^^^^^^^^^^^^^^^^^^^^^^^^^^^
  File "F:\my_linux_project\terminal_bot_serv\web_admin_telebot\venv\Lib\site-packages\django\db\backends\utils.py", line 79, in execute
    return self._execute_with_wrappers(
           ^^^^^^^^^^^^^^^^^^^^^^^^^^^^
  File "F:\my_linux_project\terminal_bot_serv\web_admin_telebot\venv\Lib\site-packages\django\db\backends\utils.py", line 92, in _execute_with_wrappers
    return executor(sql, params, many, context)
           ^^^^^^^^^^^^^^^^^^^^^^^^^^^^^^^^^^^^
  File "F:\my_linux_project\terminal_bot_serv\web_admin_telebot\venv\Lib\site-packages\django\db\backends\utils.py", line 100, in _execute
    with self.db.wrap_database_errors:
  File "F:\my_linux_project\terminal_bot_serv\web_admin_telebot\venv\Lib\site-packages\django\db\utils.py", line 91, in __exit__
    raise dj_exc_value.with_traceback(traceback) from exc_value
  File "F:\my_linux_project\terminal_bot_serv\web_admin_telebot\venv\Lib\site-packages\django\db\backends\utils.py", line 105, in _execute
    return self.cursor.execute(sql, params)
           ^^^^^^^^^^^^^^^^^^^^^^^^^^^^^^^^
  File "F:\my_linux_project\terminal_bot_serv\web_admin_telebot\venv\Lib\site-packages\django\db\backends\sqlite3\base.py", line 328, in execute
    return super().execute(query, params)
           ^^^^^^^^^^^^^^^^^^^^^^^^^^^^^^
django.db.utils.OperationalError: no such table: django_session
ERROR 2024-01-17 03:16:44,018 basehttp 18092 20360 "GET /tele_api/ HTTP/1.1" 500 234458
INFO 2024-01-17 03:17:22,567 autoreload 13720 19196 Watching for file changes with StatReloader
INFO 2024-01-17 03:17:27,075 basehttp 13720 3096 "GET /tele_api/ HTTP/1.1" 200 5176
INFO 2024-01-17 03:17:27,189 basehttp 13720 3096 "GET /static/rest_framework/css/bootstrap.min.css HTTP/1.1" 200 121457
INFO 2024-01-17 03:17:27,192 basehttp 13720 3096 "GET /static/rest_framework/js/csrf.js HTTP/1.1" 200 1719
INFO 2024-01-17 03:17:27,193 basehttp 13720 17596 "GET /static/rest_framework/css/bootstrap-tweaks.css HTTP/1.1" 200 3385
INFO 2024-01-17 03:17:27,200 basehttp 13720 18564 "GET /static/rest_framework/css/default.css HTTP/1.1" 200 1152
INFO 2024-01-17 03:17:27,203 basehttp 13720 17596 "GET /static/rest_framework/js/prettify-min.js HTTP/1.1" 200 13632
INFO 2024-01-17 03:17:27,203 basehttp 13720 3096 "GET /static/rest_framework/js/bootstrap.min.js HTTP/1.1" 200 39680
INFO 2024-01-17 03:17:27,203 basehttp 13720 20328 "GET /static/rest_framework/css/prettify.css HTTP/1.1" 200 817
INFO 2024-01-17 03:17:27,204 basehttp 13720 11716 "GET /static/rest_framework/js/ajax-form.js HTTP/1.1" 200 3597
INFO 2024-01-17 03:17:27,206 basehttp 13720 18564 "GET /static/rest_framework/js/default.js HTTP/1.1" 200 1268
INFO 2024-01-17 03:17:27,207 basehttp 13720 20140 "GET /static/rest_framework/js/jquery-3.5.1.min.js HTTP/1.1" 200 89476
INFO 2024-01-17 03:17:27,231 basehttp 13720 20140 "GET /static/rest_framework/img/grid.png HTTP/1.1" 200 1458
INFO 2024-01-17 03:17:33,066 basehttp 13720 20140 "GET /tele_api/ HTTP/1.1" 200 5176
INFO 2024-01-17 03:17:52,056 autoreload 13720 19196 F:\my_linux_project\terminal_bot_serv\web_admin_telebot\telegramrestapp\views.py changed, reloading.
INFO 2024-01-17 03:17:52,501 autoreload 16768 2692 Watching for file changes with StatReloader
INFO 2024-01-17 03:18:14,512 autoreload 16768 2692 F:\my_linux_project\terminal_bot_serv\web_admin_telebot\telegramrestapp\views.py changed, reloading.
INFO 2024-01-17 03:18:14,921 autoreload 3272 14372 Watching for file changes with StatReloader
INFO 2024-01-17 03:18:28,146 autoreload 11028 13236 Watching for file changes with StatReloader
INFO 2024-01-17 03:18:33,580 basehttp 11028 18404 "GET /tele_api/ HTTP/1.1" 200 6817
INFO 2024-01-17 03:18:40,550 basehttp 11028 18404 "GET /tele_api/?format=json HTTP/1.1" 200 27
WARNING 2024-01-17 03:18:54,509 log 11028 18404 Bad Request: /tele_api/
WARNING 2024-01-17 03:18:54,509 basehttp 11028 18404 "POST /tele_api/ HTTP/1.1" 400 6873
INFO 2024-01-17 03:19:02,052 basehttp 11028 18404 "POST /tele_api/ HTTP/1.1" 200 6823
INFO 2024-01-17 03:19:04,384 basehttp 11028 18404 "POST /tele_api/ HTTP/1.1" 200 6823
ERROR 2024-01-17 03:19:07,545 log 11028 18404 Internal Server Error: /tele_api/
Traceback (most recent call last):
  File "F:\my_linux_project\terminal_bot_serv\web_admin_telebot\venv\Lib\site-packages\django\core\handlers\exception.py", line 55, in inner
    response = get_response(request)
               ^^^^^^^^^^^^^^^^^^^^^
  File "F:\my_linux_project\terminal_bot_serv\web_admin_telebot\venv\Lib\site-packages\django\core\handlers\base.py", line 197, in _get_response
    response = wrapped_callback(request, *callback_args, **callback_kwargs)
               ^^^^^^^^^^^^^^^^^^^^^^^^^^^^^^^^^^^^^^^^^^^^^^^^^^^^^^^^^^^^
  File "F:\my_linux_project\terminal_bot_serv\web_admin_telebot\venv\Lib\site-packages\django\views\decorators\csrf.py", line 65, in _view_wrapper
    return view_func(request, *args, **kwargs)
           ^^^^^^^^^^^^^^^^^^^^^^^^^^^^^^^^^^^
  File "F:\my_linux_project\terminal_bot_serv\web_admin_telebot\venv\Lib\site-packages\django\views\generic\base.py", line 104, in view
    return self.dispatch(request, *args, **kwargs)
           ^^^^^^^^^^^^^^^^^^^^^^^^^^^^^^^^^^^^^^^
  File "F:\my_linux_project\terminal_bot_serv\web_admin_telebot\venv\Lib\site-packages\rest_framework\views.py", line 509, in dispatch
    response = self.handle_exception(exc)
               ^^^^^^^^^^^^^^^^^^^^^^^^^^
  File "F:\my_linux_project\terminal_bot_serv\web_admin_telebot\venv\Lib\site-packages\rest_framework\views.py", line 469, in handle_exception
    self.raise_uncaught_exception(exc)
  File "F:\my_linux_project\terminal_bot_serv\web_admin_telebot\venv\Lib\site-packages\rest_framework\views.py", line 480, in raise_uncaught_exception
    raise exc
  File "F:\my_linux_project\terminal_bot_serv\web_admin_telebot\venv\Lib\site-packages\rest_framework\views.py", line 506, in dispatch
    response = handler(request, *args, **kwargs)
               ^^^^^^^^^^^^^^^^^^^^^^^^^^^^^^^^^
  File "F:\my_linux_project\terminal_bot_serv\web_admin_telebot\telegramrestapp\views.py", line 12, in post
    cont_num = request.data.get('cont_num')
               ^^^^^^^^^^^^^^^^
AttributeError: 'int' object has no attribute 'get'
ERROR 2024-01-17 03:19:07,547 basehttp 11028 18404 "POST /tele_api/ HTTP/1.1" 500 101936
WARNING 2024-01-17 03:19:13,634 log 11028 18404 Not Found: /
WARNING 2024-01-17 03:19:13,634 basehttp 11028 18404 "GET / HTTP/1.1" 404 2493
INFO 2024-01-17 03:19:15,177 basehttp 11028 18404 "GET /tele_api/ HTTP/1.1" 200 6817
INFO 2024-01-17 03:20:00,684 autoreload 19532 17140 Watching for file changes with StatReloader
INFO 2024-01-17 03:20:03,056 basehttp 19532 15060 "GET /tele_api/ HTTP/1.1" 200 5167
INFO 2024-01-17 03:20:05,274 basehttp 19532 15060 "OPTIONS /tele_api/ HTTP/1.1" 200 5480
INFO 2024-01-17 03:20:06,383 basehttp 19532 15060 "OPTIONS /tele_api/ HTTP/1.1" 200 5480
INFO 2024-01-17 03:20:07,098 basehttp 19532 15060 "GET /tele_api/ HTTP/1.1" 200 5167
INFO 2024-01-17 03:20:07,774 basehttp 19532 15060 "GET /tele_api/ HTTP/1.1" 200 5167
INFO 2024-01-17 03:20:07,984 basehttp 19532 15060 "GET /tele_api/ HTTP/1.1" 200 5167
INFO 2024-01-17 03:20:08,187 basehttp 19532 15060 "GET /tele_api/ HTTP/1.1" 200 5167
INFO 2024-01-17 03:20:09,504 basehttp 19532 15060 "OPTIONS /tele_api/ HTTP/1.1" 200 5480
INFO 2024-01-17 03:21:24,835 autoreload 8120 14252 Watching for file changes with StatReloader
INFO 2024-01-17 03:21:27,091 basehttp 8120 4848 "GET /tele_api/ HTTP/1.1" 200 5234
INFO 2024-01-17 03:22:09,090 basehttp 8120 4848 "GET /tele_api/?cont_num=4111 HTTP/1.1" 200 5312
INFO 2024-01-17 03:22:45,732 basehttp 8120 4848 "GET /tele_api/?ContNum=HNKU6137310 HTTP/1.1" 200 5349
INFO 2024-01-17 03:24:50,504 autoreload 12188 16376 Watching for file changes with StatReloader
INFO 2024-01-17 03:24:55,631 basehttp 12188 4748 "GET /tele_api/?ContNum=HNKU6137310 HTTP/1.1" 200 92
INFO 2024-01-17 03:25:08,848 basehttp 12188 11436 "GET /tele_api/?ContNum=HNKU61389890 HTTP/1.1" 200 93
INFO 2024-01-17 03:25:10,772 basehttp 12188 4488 "GET /tele_api/?ContNum=HNKU61389890 HTTP/1.1" 200 93
INFO 2024-01-17 17:31:18,177 autoreload 15816 9376 Watching for file changes with StatReloader
WARNING 2024-01-17 17:31:19,887 log 15816 10084 Method Not Allowed: /
WARNING 2024-01-17 17:31:19,887 basehttp 15816 10084 "GET / HTTP/1.1" 405 5547
INFO 2024-01-17 17:31:19,914 basehttp 15816 10084 "GET /static/rest_framework/css/bootstrap.min.css HTTP/1.1" 304 0
INFO 2024-01-17 17:31:19,920 basehttp 15816 9276 "GET /static/rest_framework/css/bootstrap-tweaks.css HTTP/1.1" 304 0
INFO 2024-01-17 17:31:19,921 basehttp 15816 13836 "GET /static/rest_framework/css/prettify.css HTTP/1.1" 304 0
INFO 2024-01-17 17:31:19,921 basehttp 15816 10084 "GET /static/rest_framework/css/default.css HTTP/1.1" 304 0
INFO 2024-01-17 17:31:19,925 basehttp 15816 16756 "GET /static/rest_framework/js/jquery-3.5.1.min.js HTTP/1.1" 304 0
INFO 2024-01-17 17:31:19,926 basehttp 15816 9024 "GET /static/rest_framework/js/ajax-form.js HTTP/1.1" 304 0
INFO 2024-01-17 17:31:19,926 basehttp 15816 9276 "GET /static/rest_framework/js/bootstrap.min.js HTTP/1.1" 304 0
INFO 2024-01-17 17:31:19,926 basehttp 15816 13836 "GET /static/rest_framework/js/prettify-min.js HTTP/1.1" 304 0
INFO 2024-01-17 17:31:19,927 basehttp 15816 5972 "GET /static/rest_framework/js/csrf.js HTTP/1.1" 304 0
INFO 2024-01-17 17:31:19,927 basehttp 15816 10084 "GET /static/rest_framework/js/default.js HTTP/1.1" 304 0
INFO 2024-01-17 17:31:19,997 basehttp 15816 5972 "GET /static/rest_framework/img/grid.png HTTP/1.1" 200 1458
WARNING 2024-01-17 17:31:20,055 log 15816 5972 Not Found: /favicon.ico
WARNING 2024-01-17 17:31:20,056 basehttp 15816 5972 "GET /favicon.ico HTTP/1.1" 404 2535
WARNING 2024-01-17 17:31:23,069 log 15816 5972 Method Not Allowed: /
WARNING 2024-01-17 17:31:23,069 basehttp 15816 5972 "GET / HTTP/1.1" 405 5547
WARNING 2024-01-17 17:31:31,340 log 15816 5972 Bad Request: /
WARNING 2024-01-17 17:31:31,341 basehttp 15816 5972 "POST / HTTP/1.1" 400 5550
WARNING 2024-01-17 17:31:35,398 log 15816 5972 Bad Request: /
WARNING 2024-01-17 17:31:35,398 basehttp 15816 5972 "POST / HTTP/1.1" 400 5550
INFO 2024-01-17 17:32:03,957 autoreload 4208 12820 Watching for file changes with StatReloader
WARNING 2024-01-17 17:32:06,629 log 4208 3120 Bad Request: /
WARNING 2024-01-17 17:32:06,630 basehttp 4208 3120 "POST / HTTP/1.1" 400 5550
INFO 2024-01-17 17:38:14,982 autoreload 16624 9480 Watching for file changes with StatReloader
WARNING 2024-01-17 17:38:17,495 log 16624 16848 Not Found: /
WARNING 2024-01-17 17:38:17,496 basehttp 16624 16848 "GET / HTTP/1.1" 404 2517
WARNING 2024-01-17 17:38:27,854 log 16624 16848 Not Found: /status_cont
WARNING 2024-01-17 17:38:27,854 basehttp 16624 16848 "GET /status_cont HTTP/1.1" 404 2568
WARNING 2024-01-17 17:38:34,200 log 16624 16848 Not Found: /status_cont/
WARNING 2024-01-17 17:38:34,201 basehttp 16624 16848 "GET /status_cont/ HTTP/1.1" 404 2571
INFO 2024-01-17 17:38:39,785 basehttp 16624 16848 "GET /status_cont/%20None HTTP/1.1" 301 0
INFO 2024-01-17 17:38:39,801 basehttp 16624 1640 "GET /status_cont/%20None/ HTTP/1.1" 200 5299
INFO 2024-01-17 17:39:03,680 basehttp 16624 1640 "GET /status_cont/NEPU4571987/ HTTP/1.1" 200 5331
INFO 2024-01-17 17:40:17,689 autoreload 16468 3560 Watching for file changes with StatReloader
INFO 2024-01-17 17:40:20,126 basehttp 16468 2844 "GET /status_cont/NEPU4571987/ HTTP/1.1" 200 5511
INFO 2024-01-17 17:40:21,757 basehttp 16468 2844 "GET /status_cont/NEPU4571987/ HTTP/1.1" 200 5511
INFO 2024-01-17 17:40:27,906 basehttp 16468 2844 "GET /status_cont/NEPU4571987/?format=api HTTP/1.1" 200 5555
INFO 2024-01-17 17:40:34,407 basehttp 16468 2844 "GET /status_cont/NEPU4571987 HTTP/1.1" 301 0
INFO 2024-01-17 17:40:34,575 basehttp 16468 14904 "GET /status_cont/NEPU4571987/ HTTP/1.1" 200 5511
INFO 2024-01-17 17:41:32,176 autoreload 15812 17028 Watching for file changes with StatReloader
INFO 2024-01-17 17:41:34,809 basehttp 15812 14880 "GET /status_cont/NEPU4571987/ HTTP/1.1" 200 5537
=======
INFO 2024-01-16 21:52:47,483 autoreload 25862 139786469687296 Watching for file changes with StatReloader
INFO 2024-01-16 21:53:12,847 autoreload 25898 140201469882368 Watching for file changes with StatReloader
INFO 2024-01-16 22:32:42,720 autoreload 25998 139979417845760 Watching for file changes with StatReloader
INFO 2024-01-16 22:32:58,205 autoreload 26015 140111726616576 Watching for file changes with StatReloader
INFO 2024-01-16 22:37:02,091 autoreload 26068 139641875562496 Watching for file changes with StatReloader
INFO 2024-01-16 22:38:47,040 autoreload 26115 140445541355520 Watching for file changes with StatReloader
INFO 2024-01-16 22:45:15,333 autoreload 26169 139708794736640 Watching for file changes with StatReloader
INFO 2024-01-17 09:08:18,373 autoreload 27783 140039784800256 Watching for file changes with StatReloader
WARNING 2024-01-17 09:08:22,914 log 27783 140039623276096 Not Found: /tcl
WARNING 2024-01-17 09:08:22,915 basehttp 27783 140039623276096 "GET /tcl HTTP/1.1" 404 2514
WARNING 2024-01-17 09:08:23,089 log 27783 140039623276096 Not Found: /favicon.ico
WARNING 2024-01-17 09:08:23,089 basehttp 27783 140039623276096 "GET /favicon.ico HTTP/1.1" 404 2538
WARNING 2024-01-17 09:08:23,199 log 27783 140039707162176 Not Found: /tcl
WARNING 2024-01-17 09:08:23,199 basehttp 27783 140039707162176 "GET /tcl HTTP/1.1" 404 2514
INFO 2024-01-17 09:08:27,843 basehttp 27783 140039707162176 "GET / HTTP/1.1" 200 34
ERROR 2024-01-17 10:28:16,794 exception 30118 140702712602624 Invalid HTTP_HOST header: 'localhost'. You may need to add 'localhost' to ALLOWED_HOSTS.
Traceback (most recent call last):
  File "/home/itmadmin/terminal_bot_serv/venv/lib/python3.10/site-packages/django/core/handlers/exception.py", line 55, in inner
    response = get_response(request)
  File "/home/itmadmin/terminal_bot_serv/venv/lib/python3.10/site-packages/django/utils/deprecation.py", line 133, in __call__
    response = self.process_request(request)
  File "/home/itmadmin/terminal_bot_serv/venv/lib/python3.10/site-packages/django/middleware/common.py", line 48, in process_request
    host = request.get_host()
  File "/home/itmadmin/terminal_bot_serv/venv/lib/python3.10/site-packages/django/http/request.py", line 151, in get_host
    raise DisallowedHost(msg)
django.core.exceptions.DisallowedHost: Invalid HTTP_HOST header: 'localhost'. You may need to add 'localhost' to ALLOWED_HOSTS.
WARNING 2024-01-17 10:28:16,841 log 30118 140702712602624 Bad Request: /
ERROR 2024-01-17 10:34:54,047 exception 30118 140702712602624 Invalid HTTP_HOST header: 'localhost'. You may need to add 'localhost' to ALLOWED_HOSTS.
Traceback (most recent call last):
  File "/home/itmadmin/terminal_bot_serv/venv/lib/python3.10/site-packages/django/core/handlers/exception.py", line 55, in inner
    response = get_response(request)
  File "/home/itmadmin/terminal_bot_serv/venv/lib/python3.10/site-packages/django/utils/deprecation.py", line 133, in __call__
    response = self.process_request(request)
  File "/home/itmadmin/terminal_bot_serv/venv/lib/python3.10/site-packages/django/middleware/common.py", line 48, in process_request
    host = request.get_host()
  File "/home/itmadmin/terminal_bot_serv/venv/lib/python3.10/site-packages/django/http/request.py", line 151, in get_host
    raise DisallowedHost(msg)
django.core.exceptions.DisallowedHost: Invalid HTTP_HOST header: 'localhost'. You may need to add 'localhost' to ALLOWED_HOSTS.
WARNING 2024-01-17 10:34:54,079 log 30118 140702712602624 Bad Request: /
ERROR 2024-01-17 10:45:38,366 exception 30832 140701744082944 Invalid HTTP_HOST header: 'localhost'. You may need to add 'localhost' to ALLOWED_HOSTS.
Traceback (most recent call last):
  File "/home/itmadmin/terminal_bot_serv/venv/lib/python3.10/site-packages/django/core/handlers/exception.py", line 55, in inner
    response = get_response(request)
  File "/home/itmadmin/terminal_bot_serv/venv/lib/python3.10/site-packages/django/utils/deprecation.py", line 133, in __call__
    response = self.process_request(request)
  File "/home/itmadmin/terminal_bot_serv/venv/lib/python3.10/site-packages/django/middleware/common.py", line 48, in process_request
    host = request.get_host()
  File "/home/itmadmin/terminal_bot_serv/venv/lib/python3.10/site-packages/django/http/request.py", line 151, in get_host
    raise DisallowedHost(msg)
django.core.exceptions.DisallowedHost: Invalid HTTP_HOST header: 'localhost'. You may need to add 'localhost' to ALLOWED_HOSTS.
WARNING 2024-01-17 10:45:38,414 log 30832 140701744082944 Bad Request: /
INFO 2024-01-17 10:54:36,446 autoreload 31162 139746575396864 Watching for file changes with StatReloader
>>>>>>> cc3281f (not commit)
INFO 2024-01-17 13:13:59,588 autoreload 33852 140036590149632 Watching for file changes with StatReloader
ERROR 2024-01-17 14:38:47,771 exception 34345 140166731849728 Invalid HTTP_HOST header: '83.68.49.221:25080'. You may need to add '83.68.49.221' to ALLOWED_HOSTS.
Traceback (most recent call last):
  File "/home/itmadmin/terminal_bot_serv/venv/lib/python3.10/site-packages/django/core/handlers/exception.py", line 55, in inner
    response = get_response(request)
  File "/home/itmadmin/terminal_bot_serv/venv/lib/python3.10/site-packages/django/utils/deprecation.py", line 133, in __call__
    response = self.process_request(request)
  File "/home/itmadmin/terminal_bot_serv/venv/lib/python3.10/site-packages/django/middleware/common.py", line 48, in process_request
    host = request.get_host()
  File "/home/itmadmin/terminal_bot_serv/venv/lib/python3.10/site-packages/django/http/request.py", line 151, in get_host
    raise DisallowedHost(msg)
django.core.exceptions.DisallowedHost: Invalid HTTP_HOST header: '83.68.49.221:25080'. You may need to add '83.68.49.221' to ALLOWED_HOSTS.
WARNING 2024-01-17 14:38:47,774 log 34345 140166731849728 Bad Request: /status_cont/NEPU4570390/
ERROR 2024-01-17 14:39:29,308 exception 34347 140166731849728 Invalid HTTP_HOST header: '83.68.49.221:25080'. You may need to add '83.68.49.221' to ALLOWED_HOSTS.
Traceback (most recent call last):
  File "/home/itmadmin/terminal_bot_serv/venv/lib/python3.10/site-packages/django/core/handlers/exception.py", line 55, in inner
    response = get_response(request)
  File "/home/itmadmin/terminal_bot_serv/venv/lib/python3.10/site-packages/django/utils/deprecation.py", line 133, in __call__
    response = self.process_request(request)
  File "/home/itmadmin/terminal_bot_serv/venv/lib/python3.10/site-packages/django/middleware/common.py", line 48, in process_request
    host = request.get_host()
  File "/home/itmadmin/terminal_bot_serv/venv/lib/python3.10/site-packages/django/http/request.py", line 151, in get_host
    raise DisallowedHost(msg)
django.core.exceptions.DisallowedHost: Invalid HTTP_HOST header: '83.68.49.221:25080'. You may need to add '83.68.49.221' to ALLOWED_HOSTS.
WARNING 2024-01-17 14:39:29,310 log 34347 140166731849728 Bad Request: /status_cont/NEPU4570390/
ERROR 2024-01-17 14:39:30,476 exception 34345 140166731849728 Invalid HTTP_HOST header: '83.68.49.221:25080'. You may need to add '83.68.49.221' to ALLOWED_HOSTS.
Traceback (most recent call last):
  File "/home/itmadmin/terminal_bot_serv/venv/lib/python3.10/site-packages/django/core/handlers/exception.py", line 55, in inner
    response = get_response(request)
  File "/home/itmadmin/terminal_bot_serv/venv/lib/python3.10/site-packages/django/utils/deprecation.py", line 133, in __call__
    response = self.process_request(request)
  File "/home/itmadmin/terminal_bot_serv/venv/lib/python3.10/site-packages/django/middleware/common.py", line 48, in process_request
    host = request.get_host()
  File "/home/itmadmin/terminal_bot_serv/venv/lib/python3.10/site-packages/django/http/request.py", line 151, in get_host
    raise DisallowedHost(msg)
django.core.exceptions.DisallowedHost: Invalid HTTP_HOST header: '83.68.49.221:25080'. You may need to add '83.68.49.221' to ALLOWED_HOSTS.
WARNING 2024-01-17 14:39:30,477 log 34345 140166731849728 Bad Request: /status_cont/NEPU4570390/
ERROR 2024-01-17 14:39:31,069 exception 34345 140166731849728 Invalid HTTP_HOST header: '83.68.49.221:25080'. You may need to add '83.68.49.221' to ALLOWED_HOSTS.
Traceback (most recent call last):
  File "/home/itmadmin/terminal_bot_serv/venv/lib/python3.10/site-packages/django/core/handlers/exception.py", line 55, in inner
    response = get_response(request)
  File "/home/itmadmin/terminal_bot_serv/venv/lib/python3.10/site-packages/django/utils/deprecation.py", line 133, in __call__
    response = self.process_request(request)
  File "/home/itmadmin/terminal_bot_serv/venv/lib/python3.10/site-packages/django/middleware/common.py", line 48, in process_request
    host = request.get_host()
  File "/home/itmadmin/terminal_bot_serv/venv/lib/python3.10/site-packages/django/http/request.py", line 151, in get_host
    raise DisallowedHost(msg)
django.core.exceptions.DisallowedHost: Invalid HTTP_HOST header: '83.68.49.221:25080'. You may need to add '83.68.49.221' to ALLOWED_HOSTS.
WARNING 2024-01-17 14:39:31,070 log 34345 140166731849728 Bad Request: /status_cont/NEPU4570390/
ERROR 2024-01-17 14:39:31,226 exception 34345 140166731849728 Invalid HTTP_HOST header: '83.68.49.221:25080'. You may need to add '83.68.49.221' to ALLOWED_HOSTS.
Traceback (most recent call last):
  File "/home/itmadmin/terminal_bot_serv/venv/lib/python3.10/site-packages/django/core/handlers/exception.py", line 55, in inner
    response = get_response(request)
  File "/home/itmadmin/terminal_bot_serv/venv/lib/python3.10/site-packages/django/utils/deprecation.py", line 133, in __call__
    response = self.process_request(request)
  File "/home/itmadmin/terminal_bot_serv/venv/lib/python3.10/site-packages/django/middleware/common.py", line 48, in process_request
    host = request.get_host()
  File "/home/itmadmin/terminal_bot_serv/venv/lib/python3.10/site-packages/django/http/request.py", line 151, in get_host
    raise DisallowedHost(msg)
django.core.exceptions.DisallowedHost: Invalid HTTP_HOST header: '83.68.49.221:25080'. You may need to add '83.68.49.221' to ALLOWED_HOSTS.
WARNING 2024-01-17 14:39:31,227 log 34345 140166731849728 Bad Request: /status_cont/NEPU4570390/
ERROR 2024-01-17 14:39:31,394 exception 34345 140166731849728 Invalid HTTP_HOST header: '83.68.49.221:25080'. You may need to add '83.68.49.221' to ALLOWED_HOSTS.
Traceback (most recent call last):
  File "/home/itmadmin/terminal_bot_serv/venv/lib/python3.10/site-packages/django/core/handlers/exception.py", line 55, in inner
    response = get_response(request)
  File "/home/itmadmin/terminal_bot_serv/venv/lib/python3.10/site-packages/django/utils/deprecation.py", line 133, in __call__
    response = self.process_request(request)
  File "/home/itmadmin/terminal_bot_serv/venv/lib/python3.10/site-packages/django/middleware/common.py", line 48, in process_request
    host = request.get_host()
  File "/home/itmadmin/terminal_bot_serv/venv/lib/python3.10/site-packages/django/http/request.py", line 151, in get_host
    raise DisallowedHost(msg)
django.core.exceptions.DisallowedHost: Invalid HTTP_HOST header: '83.68.49.221:25080'. You may need to add '83.68.49.221' to ALLOWED_HOSTS.
WARNING 2024-01-17 14:39:31,395 log 34345 140166731849728 Bad Request: /status_cont/NEPU4570390/
ERROR 2024-01-17 14:39:31,572 exception 34345 140166731849728 Invalid HTTP_HOST header: '83.68.49.221:25080'. You may need to add '83.68.49.221' to ALLOWED_HOSTS.
Traceback (most recent call last):
  File "/home/itmadmin/terminal_bot_serv/venv/lib/python3.10/site-packages/django/core/handlers/exception.py", line 55, in inner
    response = get_response(request)
  File "/home/itmadmin/terminal_bot_serv/venv/lib/python3.10/site-packages/django/utils/deprecation.py", line 133, in __call__
    response = self.process_request(request)
  File "/home/itmadmin/terminal_bot_serv/venv/lib/python3.10/site-packages/django/middleware/common.py", line 48, in process_request
    host = request.get_host()
  File "/home/itmadmin/terminal_bot_serv/venv/lib/python3.10/site-packages/django/http/request.py", line 151, in get_host
    raise DisallowedHost(msg)
django.core.exceptions.DisallowedHost: Invalid HTTP_HOST header: '83.68.49.221:25080'. You may need to add '83.68.49.221' to ALLOWED_HOSTS.
WARNING 2024-01-17 14:39:31,572 log 34345 140166731849728 Bad Request: /status_cont/NEPU4570390/
ERROR 2024-01-17 14:39:44,323 exception 34345 140166731849728 Invalid HTTP_HOST header: '83.68.49.221:25080'. You may need to add '83.68.49.221' to ALLOWED_HOSTS.
Traceback (most recent call last):
  File "/home/itmadmin/terminal_bot_serv/venv/lib/python3.10/site-packages/django/core/handlers/exception.py", line 55, in inner
    response = get_response(request)
  File "/home/itmadmin/terminal_bot_serv/venv/lib/python3.10/site-packages/django/utils/deprecation.py", line 133, in __call__
    response = self.process_request(request)
  File "/home/itmadmin/terminal_bot_serv/venv/lib/python3.10/site-packages/django/middleware/common.py", line 48, in process_request
    host = request.get_host()
  File "/home/itmadmin/terminal_bot_serv/venv/lib/python3.10/site-packages/django/http/request.py", line 151, in get_host
    raise DisallowedHost(msg)
django.core.exceptions.DisallowedHost: Invalid HTTP_HOST header: '83.68.49.221:25080'. You may need to add '83.68.49.221' to ALLOWED_HOSTS.
WARNING 2024-01-17 14:39:44,324 log 34345 140166731849728 Bad Request: /status_cont/NEPU4570390/
ERROR 2024-01-17 14:39:48,608 exception 34347 140166731849728 Invalid HTTP_HOST header: '83.68.49.221:25080'. You may need to add '83.68.49.221' to ALLOWED_HOSTS.
Traceback (most recent call last):
  File "/home/itmadmin/terminal_bot_serv/venv/lib/python3.10/site-packages/django/core/handlers/exception.py", line 55, in inner
    response = get_response(request)
  File "/home/itmadmin/terminal_bot_serv/venv/lib/python3.10/site-packages/django/utils/deprecation.py", line 133, in __call__
    response = self.process_request(request)
  File "/home/itmadmin/terminal_bot_serv/venv/lib/python3.10/site-packages/django/middleware/common.py", line 48, in process_request
    host = request.get_host()
  File "/home/itmadmin/terminal_bot_serv/venv/lib/python3.10/site-packages/django/http/request.py", line 151, in get_host
    raise DisallowedHost(msg)
django.core.exceptions.DisallowedHost: Invalid HTTP_HOST header: '83.68.49.221:25080'. You may need to add '83.68.49.221' to ALLOWED_HOSTS.
WARNING 2024-01-17 14:39:48,609 log 34347 140166731849728 Bad Request: /status_cont/NEPU4570390/
ERROR 2024-01-17 14:50:29,891 exception 34345 140166731849728 Invalid HTTP_HOST header: '83.68.49.221:25080'. You may need to add '83.68.49.221' to ALLOWED_HOSTS.
Traceback (most recent call last):
  File "/home/itmadmin/terminal_bot_serv/venv/lib/python3.10/site-packages/django/core/handlers/exception.py", line 55, in inner
    response = get_response(request)
  File "/home/itmadmin/terminal_bot_serv/venv/lib/python3.10/site-packages/django/utils/deprecation.py", line 133, in __call__
    response = self.process_request(request)
  File "/home/itmadmin/terminal_bot_serv/venv/lib/python3.10/site-packages/django/middleware/common.py", line 48, in process_request
    host = request.get_host()
  File "/home/itmadmin/terminal_bot_serv/venv/lib/python3.10/site-packages/django/http/request.py", line 151, in get_host
    raise DisallowedHost(msg)
django.core.exceptions.DisallowedHost: Invalid HTTP_HOST header: '83.68.49.221:25080'. You may need to add '83.68.49.221' to ALLOWED_HOSTS.
WARNING 2024-01-17 14:50:29,893 log 34345 140166731849728 Bad Request: /status_cont/NEPU4570390/
ERROR 2024-01-17 14:50:30,696 exception 34345 140166731849728 Invalid HTTP_HOST header: '83.68.49.221:25080'. You may need to add '83.68.49.221' to ALLOWED_HOSTS.
Traceback (most recent call last):
  File "/home/itmadmin/terminal_bot_serv/venv/lib/python3.10/site-packages/django/core/handlers/exception.py", line 55, in inner
    response = get_response(request)
  File "/home/itmadmin/terminal_bot_serv/venv/lib/python3.10/site-packages/django/utils/deprecation.py", line 133, in __call__
    response = self.process_request(request)
  File "/home/itmadmin/terminal_bot_serv/venv/lib/python3.10/site-packages/django/middleware/common.py", line 48, in process_request
    host = request.get_host()
  File "/home/itmadmin/terminal_bot_serv/venv/lib/python3.10/site-packages/django/http/request.py", line 151, in get_host
    raise DisallowedHost(msg)
django.core.exceptions.DisallowedHost: Invalid HTTP_HOST header: '83.68.49.221:25080'. You may need to add '83.68.49.221' to ALLOWED_HOSTS.
WARNING 2024-01-17 14:50:30,696 log 34345 140166731849728 Bad Request: /status_cont/NEPU4570390/
ERROR 2024-01-17 14:50:30,856 exception 34347 140166731849728 Invalid HTTP_HOST header: '83.68.49.221:25080'. You may need to add '83.68.49.221' to ALLOWED_HOSTS.
Traceback (most recent call last):
  File "/home/itmadmin/terminal_bot_serv/venv/lib/python3.10/site-packages/django/core/handlers/exception.py", line 55, in inner
    response = get_response(request)
  File "/home/itmadmin/terminal_bot_serv/venv/lib/python3.10/site-packages/django/utils/deprecation.py", line 133, in __call__
    response = self.process_request(request)
  File "/home/itmadmin/terminal_bot_serv/venv/lib/python3.10/site-packages/django/middleware/common.py", line 48, in process_request
    host = request.get_host()
  File "/home/itmadmin/terminal_bot_serv/venv/lib/python3.10/site-packages/django/http/request.py", line 151, in get_host
    raise DisallowedHost(msg)
django.core.exceptions.DisallowedHost: Invalid HTTP_HOST header: '83.68.49.221:25080'. You may need to add '83.68.49.221' to ALLOWED_HOSTS.
WARNING 2024-01-17 14:50:30,858 log 34347 140166731849728 Bad Request: /status_cont/NEPU4570390/
ERROR 2024-01-17 14:50:31,034 exception 34345 140166731849728 Invalid HTTP_HOST header: '83.68.49.221:25080'. You may need to add '83.68.49.221' to ALLOWED_HOSTS.
Traceback (most recent call last):
  File "/home/itmadmin/terminal_bot_serv/venv/lib/python3.10/site-packages/django/core/handlers/exception.py", line 55, in inner
    response = get_response(request)
  File "/home/itmadmin/terminal_bot_serv/venv/lib/python3.10/site-packages/django/utils/deprecation.py", line 133, in __call__
    response = self.process_request(request)
  File "/home/itmadmin/terminal_bot_serv/venv/lib/python3.10/site-packages/django/middleware/common.py", line 48, in process_request
    host = request.get_host()
  File "/home/itmadmin/terminal_bot_serv/venv/lib/python3.10/site-packages/django/http/request.py", line 151, in get_host
    raise DisallowedHost(msg)
django.core.exceptions.DisallowedHost: Invalid HTTP_HOST header: '83.68.49.221:25080'. You may need to add '83.68.49.221' to ALLOWED_HOSTS.
WARNING 2024-01-17 14:50:31,034 log 34345 140166731849728 Bad Request: /status_cont/NEPU4570390/
WARNING 2024-01-17 14:54:25,134 log 34345 140166731849728 Not Found: /
WARNING 2024-01-17 14:54:25,662 log 34345 140166731849728 Not Found: /
WARNING 2024-01-17 14:54:34,373 log 34345 140166731849728 Not Found: /status_cont/NEPU4570390/
WARNING 2024-01-17 16:23:15,844 log 34346 140166731849728 Not Found: /status_cont/NEPU4570390/83.68.49.221
WARNING 2024-01-17 16:23:17,859 log 34346 140166731849728 Not Found: /status_cont/NEPU4570390/83.68.49.221
WARNING 2024-01-17 16:27:10,795 log 34345 140166731849728 Not Found: /status_cont/NEPU4570390/83.68.49.221
WARNING 2024-01-17 16:27:12,606 log 34345 140166731849728 Not Found: /status_cont/NEPU4570390/83.68.49.221
WARNING 2024-01-17 16:27:15,237 log 34345 140166731849728 Not Found: /status_cont/NEPU4570390/83.68.49.221
WARNING 2024-01-17 16:52:48,947 log 34347 140166731849728 Not Found: /status_cont/NEPU4570390/83.68.49.221
WARNING 2024-01-17 16:52:50,587 log 34347 140166731849728 Not Found: /status_cont/NEPU4570390/83.68.49.221
WARNING 2024-01-17 16:52:57,072 log 34347 140166731849728 Not Found: /status_cont/NEPU4570390/83.68.49.221
WARNING 2024-01-17 16:54:18,815 log 34347 140166731849728 Not Found: /status_cont/NEPU4570390/83.68.49.221
WARNING 2024-01-17 16:54:32,659 log 34345 140166731849728 Not Found: /status_cont/NEPU4570390/83.68.49.221
WARNING 2024-01-17 16:54:37,286 log 34347 140166731849728 Not Found: /status_cont/NEPU4570390/83.68.49.221
WARNING 2024-01-17 16:54:40,357 log 34345 140166731849728 Not Found: /status_cont/NEPU4570390/83.68.49.221
WARNING 2024-01-17 16:54:58,218 log 34345 140166731849728 Not Found: /status_cont/NEPU4570390/83.68.49.221
WARNING 2024-01-17 16:55:01,580 log 34347 140166731849728 Not Found: /status_cont/NEPU4570390/83.68.49.221
WARNING 2024-01-17 16:55:05,254 log 34347 140166731849728 Not Found: /status_cont/NEPU4570390/83.68.49.221
WARNING 2024-01-17 16:57:56,170 log 34345 140166731849728 Not Found: /status_cont/NEPU4570390/83.68.49.221
WARNING 2024-01-17 16:57:58,891 log 34346 140166731849728 Not Found: /status_cont/NEPU4570390/83.68.49.221
WARNING 2024-01-17 16:59:14,344 log 34345 140166731849728 Not Found: /status_cont/NEPU4570390/83.68.49.221
WARNING 2024-01-17 16:59:16,682 log 34345 140166731849728 Not Found: /status_cont/NEPU4570390/83.68.49.221
ERROR 2024-01-17 18:06:19,111 exception 34346 140166731849728 Invalid HTTP_HOST header: '83.68.49.221:25080'. You may need to add '83.68.49.221' to ALLOWED_HOSTS.
Traceback (most recent call last):
  File "/home/itmadmin/terminal_bot_serv/venv/lib/python3.10/site-packages/django/core/handlers/exception.py", line 55, in inner
    response = get_response(request)
  File "/home/itmadmin/terminal_bot_serv/venv/lib/python3.10/site-packages/django/utils/deprecation.py", line 133, in __call__
    response = self.process_request(request)
  File "/home/itmadmin/terminal_bot_serv/venv/lib/python3.10/site-packages/django/middleware/common.py", line 48, in process_request
    host = request.get_host()
  File "/home/itmadmin/terminal_bot_serv/venv/lib/python3.10/site-packages/django/http/request.py", line 151, in get_host
    raise DisallowedHost(msg)
django.core.exceptions.DisallowedHost: Invalid HTTP_HOST header: '83.68.49.221:25080'. You may need to add '83.68.49.221' to ALLOWED_HOSTS.
WARNING 2024-01-17 18:06:19,113 log 34346 140166731849728 Bad Request: /status_cont/NEPU4570390/
ERROR 2024-01-17 18:06:21,717 exception 34346 140166731849728 Invalid HTTP_HOST header: '83.68.49.221:25080'. You may need to add '83.68.49.221' to ALLOWED_HOSTS.
Traceback (most recent call last):
  File "/home/itmadmin/terminal_bot_serv/venv/lib/python3.10/site-packages/django/core/handlers/exception.py", line 55, in inner
    response = get_response(request)
  File "/home/itmadmin/terminal_bot_serv/venv/lib/python3.10/site-packages/django/utils/deprecation.py", line 133, in __call__
    response = self.process_request(request)
  File "/home/itmadmin/terminal_bot_serv/venv/lib/python3.10/site-packages/django/middleware/common.py", line 48, in process_request
    host = request.get_host()
  File "/home/itmadmin/terminal_bot_serv/venv/lib/python3.10/site-packages/django/http/request.py", line 151, in get_host
    raise DisallowedHost(msg)
django.core.exceptions.DisallowedHost: Invalid HTTP_HOST header: '83.68.49.221:25080'. You may need to add '83.68.49.221' to ALLOWED_HOSTS.
WARNING 2024-01-17 18:06:21,717 log 34346 140166731849728 Bad Request: /status_cont/NEPU4570390/
ERROR 2024-01-17 18:06:23,283 exception 34346 140166731849728 Invalid HTTP_HOST header: '83.68.49.221:25080'. You may need to add '83.68.49.221' to ALLOWED_HOSTS.
Traceback (most recent call last):
  File "/home/itmadmin/terminal_bot_serv/venv/lib/python3.10/site-packages/django/core/handlers/exception.py", line 55, in inner
    response = get_response(request)
  File "/home/itmadmin/terminal_bot_serv/venv/lib/python3.10/site-packages/django/utils/deprecation.py", line 133, in __call__
    response = self.process_request(request)
  File "/home/itmadmin/terminal_bot_serv/venv/lib/python3.10/site-packages/django/middleware/common.py", line 48, in process_request
    host = request.get_host()
  File "/home/itmadmin/terminal_bot_serv/venv/lib/python3.10/site-packages/django/http/request.py", line 151, in get_host
    raise DisallowedHost(msg)
django.core.exceptions.DisallowedHost: Invalid HTTP_HOST header: '83.68.49.221:25080'. You may need to add '83.68.49.221' to ALLOWED_HOSTS.
WARNING 2024-01-17 18:06:23,284 log 34346 140166731849728 Bad Request: /status_cont/NEPU4570390/
ERROR 2024-01-17 18:06:27,496 exception 34346 140166731849728 Invalid HTTP_HOST header: '83.68.49.221:25080'. You may need to add '83.68.49.221' to ALLOWED_HOSTS.
Traceback (most recent call last):
  File "/home/itmadmin/terminal_bot_serv/venv/lib/python3.10/site-packages/django/core/handlers/exception.py", line 55, in inner
    response = get_response(request)
  File "/home/itmadmin/terminal_bot_serv/venv/lib/python3.10/site-packages/django/utils/deprecation.py", line 133, in __call__
    response = self.process_request(request)
  File "/home/itmadmin/terminal_bot_serv/venv/lib/python3.10/site-packages/django/middleware/common.py", line 48, in process_request
    host = request.get_host()
  File "/home/itmadmin/terminal_bot_serv/venv/lib/python3.10/site-packages/django/http/request.py", line 151, in get_host
    raise DisallowedHost(msg)
django.core.exceptions.DisallowedHost: Invalid HTTP_HOST header: '83.68.49.221:25080'. You may need to add '83.68.49.221' to ALLOWED_HOSTS.
WARNING 2024-01-17 18:06:27,497 log 34346 140166731849728 Bad Request: /status_cont/NEPU4570390/
ERROR 2024-01-17 18:06:29,147 exception 34346 140166731849728 Invalid HTTP_HOST header: '83.68.49.221:25080'. You may need to add '83.68.49.221' to ALLOWED_HOSTS.
Traceback (most recent call last):
  File "/home/itmadmin/terminal_bot_serv/venv/lib/python3.10/site-packages/django/core/handlers/exception.py", line 55, in inner
    response = get_response(request)
  File "/home/itmadmin/terminal_bot_serv/venv/lib/python3.10/site-packages/django/utils/deprecation.py", line 133, in __call__
    response = self.process_request(request)
  File "/home/itmadmin/terminal_bot_serv/venv/lib/python3.10/site-packages/django/middleware/common.py", line 48, in process_request
    host = request.get_host()
  File "/home/itmadmin/terminal_bot_serv/venv/lib/python3.10/site-packages/django/http/request.py", line 151, in get_host
    raise DisallowedHost(msg)
django.core.exceptions.DisallowedHost: Invalid HTTP_HOST header: '83.68.49.221:25080'. You may need to add '83.68.49.221' to ALLOWED_HOSTS.
WARNING 2024-01-17 18:06:29,147 log 34346 140166731849728 Bad Request: /status_cont/NEPU4570390/
ERROR 2024-01-17 18:06:30,717 exception 34346 140166731849728 Invalid HTTP_HOST header: '83.68.49.221:25080'. You may need to add '83.68.49.221' to ALLOWED_HOSTS.
Traceback (most recent call last):
  File "/home/itmadmin/terminal_bot_serv/venv/lib/python3.10/site-packages/django/core/handlers/exception.py", line 55, in inner
    response = get_response(request)
  File "/home/itmadmin/terminal_bot_serv/venv/lib/python3.10/site-packages/django/utils/deprecation.py", line 133, in __call__
    response = self.process_request(request)
  File "/home/itmadmin/terminal_bot_serv/venv/lib/python3.10/site-packages/django/middleware/common.py", line 48, in process_request
    host = request.get_host()
  File "/home/itmadmin/terminal_bot_serv/venv/lib/python3.10/site-packages/django/http/request.py", line 151, in get_host
    raise DisallowedHost(msg)
django.core.exceptions.DisallowedHost: Invalid HTTP_HOST header: '83.68.49.221:25080'. You may need to add '83.68.49.221' to ALLOWED_HOSTS.
WARNING 2024-01-17 18:06:30,718 log 34346 140166731849728 Bad Request: /status_cont/NEPU4570390/
ERROR 2024-01-17 18:08:12,224 exception 34345 140166731849728 Invalid HTTP_HOST header: '83.68.49.221:33080'. You may need to add '83.68.49.221' to ALLOWED_HOSTS.
Traceback (most recent call last):
  File "/home/itmadmin/terminal_bot_serv/venv/lib/python3.10/site-packages/django/core/handlers/exception.py", line 55, in inner
    response = get_response(request)
  File "/home/itmadmin/terminal_bot_serv/venv/lib/python3.10/site-packages/django/utils/deprecation.py", line 133, in __call__
    response = self.process_request(request)
  File "/home/itmadmin/terminal_bot_serv/venv/lib/python3.10/site-packages/django/middleware/common.py", line 48, in process_request
    host = request.get_host()
  File "/home/itmadmin/terminal_bot_serv/venv/lib/python3.10/site-packages/django/http/request.py", line 151, in get_host
    raise DisallowedHost(msg)
django.core.exceptions.DisallowedHost: Invalid HTTP_HOST header: '83.68.49.221:33080'. You may need to add '83.68.49.221' to ALLOWED_HOSTS.
WARNING 2024-01-17 18:08:12,225 log 34345 140166731849728 Bad Request: /status_cont/NEPU4570390/
ERROR 2024-01-17 18:10:46,054 exception 34345 140166731849728 Invalid HTTP_HOST header: '83.68.49.221:33080'. You may need to add '83.68.49.221' to ALLOWED_HOSTS.
Traceback (most recent call last):
  File "/home/itmadmin/terminal_bot_serv/venv/lib/python3.10/site-packages/django/core/handlers/exception.py", line 55, in inner
    response = get_response(request)
  File "/home/itmadmin/terminal_bot_serv/venv/lib/python3.10/site-packages/django/utils/deprecation.py", line 133, in __call__
    response = self.process_request(request)
  File "/home/itmadmin/terminal_bot_serv/venv/lib/python3.10/site-packages/django/middleware/common.py", line 48, in process_request
    host = request.get_host()
  File "/home/itmadmin/terminal_bot_serv/venv/lib/python3.10/site-packages/django/http/request.py", line 151, in get_host
    raise DisallowedHost(msg)
django.core.exceptions.DisallowedHost: Invalid HTTP_HOST header: '83.68.49.221:33080'. You may need to add '83.68.49.221' to ALLOWED_HOSTS.
WARNING 2024-01-17 18:10:46,055 log 34345 140166731849728 Bad Request: /status_cont/NEPU4570390/
ERROR 2024-01-17 18:10:47,214 exception 34345 140166731849728 Invalid HTTP_HOST header: '83.68.49.221:33080'. You may need to add '83.68.49.221' to ALLOWED_HOSTS.
Traceback (most recent call last):
  File "/home/itmadmin/terminal_bot_serv/venv/lib/python3.10/site-packages/django/core/handlers/exception.py", line 55, in inner
    response = get_response(request)
  File "/home/itmadmin/terminal_bot_serv/venv/lib/python3.10/site-packages/django/utils/deprecation.py", line 133, in __call__
    response = self.process_request(request)
  File "/home/itmadmin/terminal_bot_serv/venv/lib/python3.10/site-packages/django/middleware/common.py", line 48, in process_request
    host = request.get_host()
  File "/home/itmadmin/terminal_bot_serv/venv/lib/python3.10/site-packages/django/http/request.py", line 151, in get_host
    raise DisallowedHost(msg)
django.core.exceptions.DisallowedHost: Invalid HTTP_HOST header: '83.68.49.221:33080'. You may need to add '83.68.49.221' to ALLOWED_HOSTS.
WARNING 2024-01-17 18:10:47,215 log 34345 140166731849728 Bad Request: /status_cont/NEPU4570390/
ERROR 2024-01-17 18:12:36,048 exception 34345 140166731849728 Invalid HTTP_HOST header: '83.68.49.221:33080'. You may need to add '83.68.49.221' to ALLOWED_HOSTS.
Traceback (most recent call last):
  File "/home/itmadmin/terminal_bot_serv/venv/lib/python3.10/site-packages/django/core/handlers/exception.py", line 55, in inner
    response = get_response(request)
  File "/home/itmadmin/terminal_bot_serv/venv/lib/python3.10/site-packages/django/utils/deprecation.py", line 133, in __call__
    response = self.process_request(request)
  File "/home/itmadmin/terminal_bot_serv/venv/lib/python3.10/site-packages/django/middleware/common.py", line 48, in process_request
    host = request.get_host()
  File "/home/itmadmin/terminal_bot_serv/venv/lib/python3.10/site-packages/django/http/request.py", line 151, in get_host
    raise DisallowedHost(msg)
django.core.exceptions.DisallowedHost: Invalid HTTP_HOST header: '83.68.49.221:33080'. You may need to add '83.68.49.221' to ALLOWED_HOSTS.
WARNING 2024-01-17 18:12:36,049 log 34345 140166731849728 Bad Request: /status_cont/NEPU4570390/
ERROR 2024-01-17 18:12:37,430 exception 34345 140166731849728 Invalid HTTP_HOST header: '83.68.49.221:33080'. You may need to add '83.68.49.221' to ALLOWED_HOSTS.
Traceback (most recent call last):
  File "/home/itmadmin/terminal_bot_serv/venv/lib/python3.10/site-packages/django/core/handlers/exception.py", line 55, in inner
    response = get_response(request)
  File "/home/itmadmin/terminal_bot_serv/venv/lib/python3.10/site-packages/django/utils/deprecation.py", line 133, in __call__
    response = self.process_request(request)
  File "/home/itmadmin/terminal_bot_serv/venv/lib/python3.10/site-packages/django/middleware/common.py", line 48, in process_request
    host = request.get_host()
  File "/home/itmadmin/terminal_bot_serv/venv/lib/python3.10/site-packages/django/http/request.py", line 151, in get_host
    raise DisallowedHost(msg)
django.core.exceptions.DisallowedHost: Invalid HTTP_HOST header: '83.68.49.221:33080'. You may need to add '83.68.49.221' to ALLOWED_HOSTS.
WARNING 2024-01-17 18:12:37,431 log 34345 140166731849728 Bad Request: /status_cont/NEPU4570390/
ERROR 2024-01-17 18:12:42,042 exception 34345 140166731849728 Invalid HTTP_HOST header: '83.68.49.221:33080'. You may need to add '83.68.49.221' to ALLOWED_HOSTS.
Traceback (most recent call last):
  File "/home/itmadmin/terminal_bot_serv/venv/lib/python3.10/site-packages/django/core/handlers/exception.py", line 55, in inner
    response = get_response(request)
  File "/home/itmadmin/terminal_bot_serv/venv/lib/python3.10/site-packages/django/utils/deprecation.py", line 133, in __call__
    response = self.process_request(request)
  File "/home/itmadmin/terminal_bot_serv/venv/lib/python3.10/site-packages/django/middleware/common.py", line 48, in process_request
    host = request.get_host()
  File "/home/itmadmin/terminal_bot_serv/venv/lib/python3.10/site-packages/django/http/request.py", line 151, in get_host
    raise DisallowedHost(msg)
django.core.exceptions.DisallowedHost: Invalid HTTP_HOST header: '83.68.49.221:33080'. You may need to add '83.68.49.221' to ALLOWED_HOSTS.
WARNING 2024-01-17 18:12:42,043 log 34345 140166731849728 Bad Request: /status_cont/NEPU4570390/
ERROR 2024-01-17 18:13:20,525 exception 34347 140166731849728 Invalid HTTP_HOST header: '83.68.49.221:8080'. You may need to add '83.68.49.221' to ALLOWED_HOSTS.
Traceback (most recent call last):
  File "/home/itmadmin/terminal_bot_serv/venv/lib/python3.10/site-packages/django/core/handlers/exception.py", line 55, in inner
    response = get_response(request)
  File "/home/itmadmin/terminal_bot_serv/venv/lib/python3.10/site-packages/django/utils/deprecation.py", line 133, in __call__
    response = self.process_request(request)
  File "/home/itmadmin/terminal_bot_serv/venv/lib/python3.10/site-packages/django/middleware/common.py", line 48, in process_request
    host = request.get_host()
  File "/home/itmadmin/terminal_bot_serv/venv/lib/python3.10/site-packages/django/http/request.py", line 151, in get_host
    raise DisallowedHost(msg)
django.core.exceptions.DisallowedHost: Invalid HTTP_HOST header: '83.68.49.221:8080'. You may need to add '83.68.49.221' to ALLOWED_HOSTS.
WARNING 2024-01-17 18:13:20,526 log 34347 140166731849728 Bad Request: /status_cont/NEPU4570390/
ERROR 2024-01-17 18:13:23,018 exception 34347 140166731849728 Invalid HTTP_HOST header: '83.68.49.221:8080'. You may need to add '83.68.49.221' to ALLOWED_HOSTS.
Traceback (most recent call last):
  File "/home/itmadmin/terminal_bot_serv/venv/lib/python3.10/site-packages/django/core/handlers/exception.py", line 55, in inner
    response = get_response(request)
  File "/home/itmadmin/terminal_bot_serv/venv/lib/python3.10/site-packages/django/utils/deprecation.py", line 133, in __call__
    response = self.process_request(request)
  File "/home/itmadmin/terminal_bot_serv/venv/lib/python3.10/site-packages/django/middleware/common.py", line 48, in process_request
    host = request.get_host()
  File "/home/itmadmin/terminal_bot_serv/venv/lib/python3.10/site-packages/django/http/request.py", line 151, in get_host
    raise DisallowedHost(msg)
django.core.exceptions.DisallowedHost: Invalid HTTP_HOST header: '83.68.49.221:8080'. You may need to add '83.68.49.221' to ALLOWED_HOSTS.
WARNING 2024-01-17 18:13:23,018 log 34347 140166731849728 Bad Request: /status_cont/NEPU4570390/
ERROR 2024-01-17 18:13:27,258 exception 34345 140166731849728 Invalid HTTP_HOST header: '83.68.49.221:8080'. You may need to add '83.68.49.221' to ALLOWED_HOSTS.
Traceback (most recent call last):
  File "/home/itmadmin/terminal_bot_serv/venv/lib/python3.10/site-packages/django/core/handlers/exception.py", line 55, in inner
    response = get_response(request)
  File "/home/itmadmin/terminal_bot_serv/venv/lib/python3.10/site-packages/django/utils/deprecation.py", line 133, in __call__
    response = self.process_request(request)
  File "/home/itmadmin/terminal_bot_serv/venv/lib/python3.10/site-packages/django/middleware/common.py", line 48, in process_request
    host = request.get_host()
  File "/home/itmadmin/terminal_bot_serv/venv/lib/python3.10/site-packages/django/http/request.py", line 151, in get_host
    raise DisallowedHost(msg)
django.core.exceptions.DisallowedHost: Invalid HTTP_HOST header: '83.68.49.221:8080'. You may need to add '83.68.49.221' to ALLOWED_HOSTS.
WARNING 2024-01-17 18:13:27,259 log 34345 140166731849728 Bad Request: /status_cont/NEPU4570390/
ERROR 2024-01-17 18:20:38,045 exception 34347 140166731849728 Invalid HTTP_HOST header: 'telebot.sigir.com:8080'. You may need to add 'telebot.sigir.com' to ALLOWED_HOSTS.
Traceback (most recent call last):
  File "/home/itmadmin/terminal_bot_serv/venv/lib/python3.10/site-packages/django/core/handlers/exception.py", line 55, in inner
    response = get_response(request)
  File "/home/itmadmin/terminal_bot_serv/venv/lib/python3.10/site-packages/django/utils/deprecation.py", line 133, in __call__
    response = self.process_request(request)
  File "/home/itmadmin/terminal_bot_serv/venv/lib/python3.10/site-packages/django/middleware/common.py", line 48, in process_request
    host = request.get_host()
  File "/home/itmadmin/terminal_bot_serv/venv/lib/python3.10/site-packages/django/http/request.py", line 151, in get_host
    raise DisallowedHost(msg)
django.core.exceptions.DisallowedHost: Invalid HTTP_HOST header: 'telebot.sigir.com:8080'. You may need to add 'telebot.sigir.com' to ALLOWED_HOSTS.
WARNING 2024-01-17 18:20:38,047 log 34347 140166731849728 Bad Request: /status_cont/NEPU4570390/
ERROR 2024-01-17 18:22:51,200 exception 34345 140166731849728 Invalid HTTP_HOST header: '83.68.49.221:8080'. You may need to add '83.68.49.221' to ALLOWED_HOSTS.
Traceback (most recent call last):
  File "/home/itmadmin/terminal_bot_serv/venv/lib/python3.10/site-packages/django/core/handlers/exception.py", line 55, in inner
    response = get_response(request)
  File "/home/itmadmin/terminal_bot_serv/venv/lib/python3.10/site-packages/django/utils/deprecation.py", line 133, in __call__
    response = self.process_request(request)
  File "/home/itmadmin/terminal_bot_serv/venv/lib/python3.10/site-packages/django/middleware/common.py", line 48, in process_request
    host = request.get_host()
  File "/home/itmadmin/terminal_bot_serv/venv/lib/python3.10/site-packages/django/http/request.py", line 151, in get_host
    raise DisallowedHost(msg)
django.core.exceptions.DisallowedHost: Invalid HTTP_HOST header: '83.68.49.221:8080'. You may need to add '83.68.49.221' to ALLOWED_HOSTS.
WARNING 2024-01-17 18:22:51,201 log 34345 140166731849728 Bad Request: /status_cont/NEPU4570390/
ERROR 2024-01-17 18:22:52,668 exception 34345 140166731849728 Invalid HTTP_HOST header: '83.68.49.221:8080'. You may need to add '83.68.49.221' to ALLOWED_HOSTS.
Traceback (most recent call last):
  File "/home/itmadmin/terminal_bot_serv/venv/lib/python3.10/site-packages/django/core/handlers/exception.py", line 55, in inner
    response = get_response(request)
  File "/home/itmadmin/terminal_bot_serv/venv/lib/python3.10/site-packages/django/utils/deprecation.py", line 133, in __call__
    response = self.process_request(request)
  File "/home/itmadmin/terminal_bot_serv/venv/lib/python3.10/site-packages/django/middleware/common.py", line 48, in process_request
    host = request.get_host()
  File "/home/itmadmin/terminal_bot_serv/venv/lib/python3.10/site-packages/django/http/request.py", line 151, in get_host
    raise DisallowedHost(msg)
django.core.exceptions.DisallowedHost: Invalid HTTP_HOST header: '83.68.49.221:8080'. You may need to add '83.68.49.221' to ALLOWED_HOSTS.
WARNING 2024-01-17 18:22:52,669 log 34345 140166731849728 Bad Request: /status_cont/NEPU4570390/
ERROR 2024-01-17 18:23:05,615 exception 34345 140166731849728 Invalid HTTP_HOST header: '83.68.49.221:8080'. You may need to add '83.68.49.221' to ALLOWED_HOSTS.
Traceback (most recent call last):
  File "/home/itmadmin/terminal_bot_serv/venv/lib/python3.10/site-packages/django/core/handlers/exception.py", line 55, in inner
    response = get_response(request)
  File "/home/itmadmin/terminal_bot_serv/venv/lib/python3.10/site-packages/django/utils/deprecation.py", line 133, in __call__
    response = self.process_request(request)
  File "/home/itmadmin/terminal_bot_serv/venv/lib/python3.10/site-packages/django/middleware/common.py", line 48, in process_request
    host = request.get_host()
  File "/home/itmadmin/terminal_bot_serv/venv/lib/python3.10/site-packages/django/http/request.py", line 151, in get_host
    raise DisallowedHost(msg)
django.core.exceptions.DisallowedHost: Invalid HTTP_HOST header: '83.68.49.221:8080'. You may need to add '83.68.49.221' to ALLOWED_HOSTS.
WARNING 2024-01-17 18:23:05,615 log 34345 140166731849728 Bad Request: /status_cont/NEPU4570390/
ERROR 2024-01-17 18:23:13,023 exception 34345 140166731849728 Invalid HTTP_HOST header: '83.68.49.221:8080'. You may need to add '83.68.49.221' to ALLOWED_HOSTS.
Traceback (most recent call last):
  File "/home/itmadmin/terminal_bot_serv/venv/lib/python3.10/site-packages/django/core/handlers/exception.py", line 55, in inner
    response = get_response(request)
  File "/home/itmadmin/terminal_bot_serv/venv/lib/python3.10/site-packages/django/utils/deprecation.py", line 133, in __call__
    response = self.process_request(request)
  File "/home/itmadmin/terminal_bot_serv/venv/lib/python3.10/site-packages/django/middleware/common.py", line 48, in process_request
    host = request.get_host()
  File "/home/itmadmin/terminal_bot_serv/venv/lib/python3.10/site-packages/django/http/request.py", line 151, in get_host
    raise DisallowedHost(msg)
django.core.exceptions.DisallowedHost: Invalid HTTP_HOST header: '83.68.49.221:8080'. You may need to add '83.68.49.221' to ALLOWED_HOSTS.
WARNING 2024-01-17 18:23:13,024 log 34345 140166731849728 Bad Request: /status_cont/NEPU4570390
ERROR 2024-01-17 18:23:19,751 exception 34345 140166731849728 Invalid HTTP_HOST header: '83.68.49.221:8080'. You may need to add '83.68.49.221' to ALLOWED_HOSTS.
Traceback (most recent call last):
  File "/home/itmadmin/terminal_bot_serv/venv/lib/python3.10/site-packages/django/core/handlers/exception.py", line 55, in inner
    response = get_response(request)
  File "/home/itmadmin/terminal_bot_serv/venv/lib/python3.10/site-packages/django/utils/deprecation.py", line 133, in __call__
    response = self.process_request(request)
  File "/home/itmadmin/terminal_bot_serv/venv/lib/python3.10/site-packages/django/middleware/common.py", line 48, in process_request
    host = request.get_host()
  File "/home/itmadmin/terminal_bot_serv/venv/lib/python3.10/site-packages/django/http/request.py", line 151, in get_host
    raise DisallowedHost(msg)
django.core.exceptions.DisallowedHost: Invalid HTTP_HOST header: '83.68.49.221:8080'. You may need to add '83.68.49.221' to ALLOWED_HOSTS.
WARNING 2024-01-17 18:23:19,752 log 34345 140166731849728 Bad Request: /status_cont/NEPU4570390/
ERROR 2024-01-17 18:25:03,019 exception 34346 140166731849728 Invalid HTTP_HOST header: '83.68.49.221:8080'. You may need to add '83.68.49.221' to ALLOWED_HOSTS.
Traceback (most recent call last):
  File "/home/itmadmin/terminal_bot_serv/venv/lib/python3.10/site-packages/django/core/handlers/exception.py", line 55, in inner
    response = get_response(request)
  File "/home/itmadmin/terminal_bot_serv/venv/lib/python3.10/site-packages/django/utils/deprecation.py", line 133, in __call__
    response = self.process_request(request)
  File "/home/itmadmin/terminal_bot_serv/venv/lib/python3.10/site-packages/django/middleware/common.py", line 48, in process_request
    host = request.get_host()
  File "/home/itmadmin/terminal_bot_serv/venv/lib/python3.10/site-packages/django/http/request.py", line 151, in get_host
    raise DisallowedHost(msg)
django.core.exceptions.DisallowedHost: Invalid HTTP_HOST header: '83.68.49.221:8080'. You may need to add '83.68.49.221' to ALLOWED_HOSTS.
WARNING 2024-01-17 18:25:03,020 log 34346 140166731849728 Bad Request: /status_cont/NEPU4570390/
ERROR 2024-01-17 18:25:08,095 exception 34345 140166731849728 Invalid HTTP_HOST header: '83.68.49.221:8080'. You may need to add '83.68.49.221' to ALLOWED_HOSTS.
Traceback (most recent call last):
  File "/home/itmadmin/terminal_bot_serv/venv/lib/python3.10/site-packages/django/core/handlers/exception.py", line 55, in inner
    response = get_response(request)
  File "/home/itmadmin/terminal_bot_serv/venv/lib/python3.10/site-packages/django/utils/deprecation.py", line 133, in __call__
    response = self.process_request(request)
  File "/home/itmadmin/terminal_bot_serv/venv/lib/python3.10/site-packages/django/middleware/common.py", line 48, in process_request
    host = request.get_host()
  File "/home/itmadmin/terminal_bot_serv/venv/lib/python3.10/site-packages/django/http/request.py", line 151, in get_host
    raise DisallowedHost(msg)
django.core.exceptions.DisallowedHost: Invalid HTTP_HOST header: '83.68.49.221:8080'. You may need to add '83.68.49.221' to ALLOWED_HOSTS.
WARNING 2024-01-17 18:25:08,096 log 34345 140166731849728 Bad Request: /status_cont/NEPU4570390/
WARNING 2024-01-17 20:14:07,228 log 38250 139858547417088 Not Found: /
ERROR 2024-01-17 21:11:08,911 exception 38251 139858547417088 Invalid HTTP_HOST header: '/run/gunicorn.sock:'. The domain name provided is not valid according to RFC 1034/1035.
Traceback (most recent call last):
  File "/home/itmadmin/terminal_bot_serv/venv/lib/python3.10/site-packages/django/core/handlers/exception.py", line 55, in inner
    response = get_response(request)
  File "/home/itmadmin/terminal_bot_serv/venv/lib/python3.10/site-packages/django/utils/deprecation.py", line 133, in __call__
    response = self.process_request(request)
  File "/home/itmadmin/terminal_bot_serv/venv/lib/python3.10/site-packages/django/middleware/common.py", line 48, in process_request
    host = request.get_host()
  File "/home/itmadmin/terminal_bot_serv/venv/lib/python3.10/site-packages/django/http/request.py", line 151, in get_host
    raise DisallowedHost(msg)
django.core.exceptions.DisallowedHost: Invalid HTTP_HOST header: '/run/gunicorn.sock:'. The domain name provided is not valid according to RFC 1034/1035.
WARNING 2024-01-17 21:11:08,959 log 38251 139858547417088 Bad Request: /
WARNING 2024-01-17 21:14:43,890 log 38250 139858547417088 Not Found: /actuator/health
WARNING 2024-01-17 21:31:10,066 log 38249 139858547417088 Not Found: /hudson
WARNING 2024-01-17 21:49:13,997 log 38249 139858547417088 Not Found: /goform/set_LimitClient_cfg
WARNING 2024-01-17 22:37:31,904 log 38251 139858547417088 Not Found: /
WARNING 2024-01-17 22:48:37,085 log 38251 139858547417088 Not Found: /
ERROR 2024-01-17 23:02:06,323 exception 38250 139858547417088 Invalid HTTP_HOST header: '/run/gunicorn.sock:'. The domain name provided is not valid according to RFC 1034/1035.
Traceback (most recent call last):
  File "/home/itmadmin/terminal_bot_serv/venv/lib/python3.10/site-packages/django/core/handlers/exception.py", line 55, in inner
    response = get_response(request)
  File "/home/itmadmin/terminal_bot_serv/venv/lib/python3.10/site-packages/django/utils/deprecation.py", line 133, in __call__
    response = self.process_request(request)
  File "/home/itmadmin/terminal_bot_serv/venv/lib/python3.10/site-packages/django/middleware/common.py", line 48, in process_request
    host = request.get_host()
  File "/home/itmadmin/terminal_bot_serv/venv/lib/python3.10/site-packages/django/http/request.py", line 151, in get_host
    raise DisallowedHost(msg)
django.core.exceptions.DisallowedHost: Invalid HTTP_HOST header: '/run/gunicorn.sock:'. The domain name provided is not valid according to RFC 1034/1035.
WARNING 2024-01-17 23:02:06,362 log 38250 139858547417088 Bad Request: /
WARNING 2024-01-17 23:21:05,008 log 38251 139858547417088 Not Found: /invoker/readonly
WARNING 2024-01-17 23:21:05,835 log 38251 139858547417088 Not Found: /
WARNING 2024-01-17 23:21:06,768 log 38250 139858547417088 Not Found: /script
WARNING 2024-01-17 23:21:07,590 log 38250 139858547417088 Not Found: /login
WARNING 2024-01-17 23:21:11,137 log 38251 139858547417088 Not Found: /jenkins/login
WARNING 2024-01-17 23:21:11,966 log 38249 139858547417088 Not Found: /manager/html
WARNING 2024-01-17 23:27:22,873 log 38250 139858547417088 Not Found: /
WARNING 2024-01-17 23:39:38,847 log 38250 139858547417088 Not Found: /
WARNING 2024-01-18 00:06:25,459 log 38250 139858547417088 Not Found: /
WARNING 2024-01-18 00:45:33,097 log 38251 139858547417088 Not Found: /
